<?xml version="1.0" ?>
<robot name="Rollbody2.1_test4">
  <joint name="Rollbody2.1_test4__joint_wheelsR" type="revolute">
    <parent link="Rollbody2.1_test4__link_base"/>
    <child link="Rollbody2.1_test4__wheelR"/>
    <origin xyz="-0.40372  0       0.05" rpy="0 0 0"/>
    <axis xyz="-1  0  0"/>
    <limit lower="0.0" upper="6.283185307179586" effort="0.0" velocity="0.0"/>
  </joint>
  <joint name="Rollbody2.1_test4__joint_wheelL" type="revolute">
    <parent link="Rollbody2.1_test4__link_base"/>
    <child link="Rollbody2.1_test4__wheelL"/>
    <origin xyz="0.40372 0      0.05" rpy="0 0 0"/>
    <axis xyz="1 0 0"/>
    <limit lower="0.0" upper="6.283185307179586" effort="0.0" velocity="0.0"/>
  </joint>
  <joint name="Rollbody2.1_test4__joint_loomo_head" type="revolute">
    <parent link="Rollbody2.1_test4__link_base"/>
    <child link="Rollbody2.1_test4__link_loomo_head"/>
    <origin xyz="-1.2200e-03 -2.0000e-05  7.6541e-01" rpy="0 0 0"/>
    <axis xyz="0 0 1"/>
    <limit lower="0.0" upper="6.283185307179586" effort="0.0" velocity="0.0"/>
  </joint>
  <joint name="Rollbody2.1_test4__joint_heightAdjust" type="prismatic">
    <parent link="Rollbody2.1_test4__link_base"/>
    <child link="Rollbody2.1_test4__link_heightAdjust"/>
    <origin xyz="0      -0.03     2.22371" rpy="0 0 0"/>
    <axis xyz="0 0 1"/>
    <limit lower="-0.25" upper="0.25" effort="0.0" velocity="0.0"/>
  </joint>
  <link name="Rollbody2.1_test4__link_heightAdjust">
    <inertial>
      <mass value="2.9809715023306786"/>
      <origin xyz="0 0 0" rpy="0 0 0"/>
      <inertia ixx="4.941734819431478" ixy="-1.6443664081913173e-15" ixz="5.589880077394383e-14" iyy="4.9407120272463905" iyz="0.08122179996364012" izz="0.002546465257724052"/>
    </inertial>
    <collision name="Rollbody2.1_test4__link_heightAdjust_collision">
      <origin xyz="0      0.01   -0.9545" rpy="0 0 0"/>
      <geometry>
        <mesh filename="package://PATHTOMESHES/meshes/CAD/link_heightAdjust.stl" scale="0.001 0.001 0.001"/>
      </geometry>
    </collision>
    <visual name="Rollbody2.1_test4__link_heightAdjust_visual">
      <origin xyz="0      0.01   -0.9545" rpy="0 0 0"/>
      <geometry>
        <mesh filename="package://PATHTOMESHES/meshes/CAD/link_heightAdjust.stl" scale="0.001 0.001 0.001"/>
      </geometry>
    </visual>
  </link>
  <link name="Rollbody2.1_test4__link_base">
    <inertial>
      <mass value="86.1777122467262"/>
      <origin xyz="0 0 0" rpy="0 0 0"/>
      <inertia ixx="6.443231636530824" ixy="0.0006993266805764146" ixz="0.002440526189443658" iyy="6.388071337224328" iyz="-0.0721928133558915" izz="1.802654637421469"/>
    </inertial>
    <collision name="Rollbody2.1_test4__link_base_collision">
      <origin xyz="-0.00079  0.00574  0.15327" rpy="0 0 0"/>
      <geometry>
        <mesh filename="package://PATHTOMESHES/meshes/CAD/link_base.stl" scale="0.001 0.001 0.001"/>
      </geometry>
    </collision>
    <visual name="Rollbody2.1_test4__link_base_visual">
      <origin xyz="-0.00079  0.00574  0.15327" rpy="0 0 0"/>
      <geometry>
        <mesh filename="package://PATHTOMESHES/meshes/CAD/link_base.stl" scale="0.001 0.001 0.001"/>
      </geometry>
    </visual>
  </link>
  <link name="Rollbody2.1_test4__link_loomo_head">
    <inertial>
      <mass value="12.991942687000781"/>
      <origin xyz="0 0 0" rpy="0 0 0"/>
      <inertia ixx="2.388752916509112" ixy="-2.016858278166148e-14" ixz="0.006571408800908258" iyy="2.445335065506726" iyz="9.873591670603139e-05" izz="0.06850544130681294"/>
    </inertial>
    <collision name="Rollbody2.1_test4__link_loomo_head_collision">
      <origin xyz="0       0      -0.33848" rpy="0 0 0"/>
      <geometry>
        <mesh filename="package://PATHTOMESHES/meshes/CAD/link_loomo_head.stl" scale="0.001 0.001 0.001"/>
      </geometry>
    </collision>
    <visual name="Rollbody2.1_test4__link_loomo_head_visual">
      <origin xyz="0       0      -0.33848" rpy="0 0 0"/>
      <geometry>
        <mesh filename="package://PATHTOMESHES/meshes/CAD/link_loomo_head.stl" scale="0.001 0.001 0.001"/>
      </geometry>
    </visual>
  </link>
  <link name="Rollbody2.1_test4__wheelR">
    <inertial>
      <mass value="28.624341980085596"/>
      <origin xyz="0 0 0" rpy="0 0 0"/>
      <inertia ixx="0.29162603877351323" ixy="-9.213120576122778e-11" ixz="0.15509336178078817" iyy="1.5078493950683791" iyz="1.0613919714810214e-11" izz="1.489959218036965"/>
    </inertial>
    <collision name="Rollbody2.1_test4__wheelR_collision">
      <origin xyz="0.187  0    -0.025" rpy="0 0 0"/>
      <geometry>
        <mesh filename="package://PATHTOMESHES/meshes/CAD/wheelR.stl" scale="0.001 0.001 0.001"/>
      </geometry>
    </collision>
    <visual name="Rollbody2.1_test4__wheelR_visual">
      <origin xyz="0.187  0    -0.025" rpy="0 0 0"/>
      <geometry>
        <mesh filename="package://PATHTOMESHES/meshes/CAD/wheelR.stl" scale="0.001 0.001 0.001"/>
      </geometry>
    </visual>
  </link>
  <link name="Rollbody2.1_test4__wheelL">
    <inertial>
      <mass value="28.624341980085244"/>
      <origin xyz="0 0 0" rpy="0 0 0"/>
      <inertia ixx="0.29162604722004715" ixy="-5.801943252828305e-11" ixz="-0.15509336178078814" iyy="1.5078494077381723" iyz="-6.684359397954888e-12" izz="1.4899592138136788"/>
    </inertial>
    <collision name="Rollbody2.1_test4__wheelL_collision">
      <origin xyz="-0.187  0    -0.025" rpy="0 0 0"/>
      <geometry>
        <mesh filename="package://PATHTOMESHES/meshes/CAD/wheelL.stl" scale="0.001 0.001 0.001"/>
      </geometry>
    </collision>
    <visual name="Rollbody2.1_test4__wheelL_visual">
      <origin xyz="-0.187  0    -0.025" rpy="0 0 0"/>
      <geometry>
        <mesh filename="package://PATHTOMESHES/meshes/CAD/wheelL.stl" scale="0.001 0.001 0.001"/>
      </geometry>
    </visual>
  </link>
</robot>
