<robot name="upper_body">
  
  <joint name="head_axis0" type="revolute">
    <parent link="torso" />
    <child link="head_link1" />
    <origin rpy="0 0 0" xyz="0      0      0.84075" />
    <axis xyz="1 0 0" />
    <limit effort="1.0" lower="-0.8" upper="0.8" velocity="10.0" />
  </joint>
  <joint name="head_axis1" type="revolute">
    <parent link="head_link1" />
    <child link="head_link2" />
    <origin rpy="0 0 0" xyz="0 0 0" />
    <axis xyz="0  0 -1" />
    <limit effort="1.0" lower="-0.56" upper="0.56" velocity="10.0" />
  </joint>
  <joint name="head_axis2" type="revolute">
    <parent link="head_link2" />
    <child link="head" />
    <origin rpy="0 0 0" xyz="0 0 0" />
    <axis xyz="0 1 0" />
    <limit effort="1.0" lower="-1.0" upper="1.0" velocity="10.0" />
  </joint>
 
  <link name="head">
    <inertial>
      <mass value="2.1598514080281315" />
      <origin rpy="0 0 0" xyz="-0.0002  -0.01814  0.1557" />
      <inertia ixx="2.1559773436970113" ixy="2.323405580889926e-05" ixz="0.0004164361828475648" iyy="2.1576901383913416" iyz="0.03738915961197302" izz="0.02811964967375591" />
    </inertial>
    <collision name="head_collision">
      <origin rpy="0 0 0" xyz="-0.0002  -0.01814  0.1557" />
      <geometry>
        <mesh filename="meshes/collada_collisions/head.dae" scale="0.001 0.001 0.001" />
      </geometry>
    </collision>
    <visual name="head_visual">
      <origin rpy="0 0 0" xyz="-0.0002  -0.01814  0.1557" />
      <geometry>
        <mesh filename="meshes/collada_visuals/head.dae" scale="0.001 0.001 0.001" />
      </geometry>
    </visual>
  </link>
  <link name="torso">
    <inertial>
      <mass value="25.160471303342216" />
      <origin rpy="0 0 0" xyz="0.00776 0.00282 0.62658" />
      <inertia ixx="10.398585859477636" ixy="0.00015013373897767912" ixz="-0.10586365499644151" iyy="10.58255768903264" iyz="-0.05807739632925058" izz="0.4658890640245697" />
    </inertial>
    <collision name="torso_collision">
      <origin rpy="0 0 0" xyz="0.00776 0.00282 0.62658" />
      <geometry>
        <mesh filename="meshes/collada_collisions/torso.dae" scale="0.001 0.001 0.001" />
      </geometry>
    </collision>
    <visual name="torso_visual">
      <origin rpy="0 0 0" xyz="0.00776 0.00282 0.62658" />
      <geometry>
        <mesh filename="meshes/collada_visuals/torso.dae" scale="0.001 0.001 0.001" />
      </geometry>
    </visual>
  </link>
  
  <link name="head_link1">
    <inertial>
      <mass value="0.03806502884740436" />
      <origin rpy="0 0 0" xyz="0 0 0" />
      <inertia ixx="0.026908346370427178" ixy="-2.168404344971009e-22" ixz="-2.4424906541753445e-19" iyy="0.026908346370427178" iyz="5.601075159233915e-18" izz="1.6786677721705307e-06" />
    </inertial>
    <collision name="head_link1_collision">
      <origin rpy="0 0 0" xyz="0 0 0" />
      <geometry>
        <mesh filename="meshes/collada_collisions/head_link1.dae" scale="0.001 0.001 0.001" />
      </geometry>
    </collision>
    <visual name="head_link1_visual">
      <origin rpy="0 0 0" xyz="0 0 0" />
      <geometry>
        <mesh filename="meshes/collada_visuals/head_link1.dae" scale="0.001 0.001 0.001" />
      </geometry>
    </visual>
  </link>
  <link name="head_link2">
    <inertial>
      <mass value="0.002996372533177606" />
      <origin rpy="0 0 0" xyz="0 0 0" />
      <inertia ixx="0.002118041844878994" ixy="3.404394821608228e-24" ixz="-1.78481526433294e-20" iyy="0.002118041844878994" iyz="4.440892098500626e-19" izz="2.427061751873877e-08" />
    </inertial>
    <collision name="head_link2_collision">
      <origin rpy="0 0 0" xyz="0 0 0" />
      <geometry>
        <mesh filename="meshes/collada_collisions/head_link2.dae" scale="0.001 0.001 0.001" />
      </geometry>
    </collision>
    <visual name="head_link2_visual">
      <origin rpy="0 0 0" xyz="0 0 0" />
      <geometry>
        <mesh filename="meshes/collada_visuals/head_link2.dae" scale="0.001 0.001 0.001" />
      </geometry>
    </visual>
  </link>


</robot>
