<?xml version="1.0" ?>
<robot name="">
  <joint name="joint_wheelL" type="revolute">
    <parent link="link_base"/>
    <child link="link_wheelL"/>
    <origin xyz="0.40372 0      0.05" rpy="0 0 0"/>
    <axis xyz="1 0 0"/>
    <limit lower="0.0" upper="6.283185307179586" effort="0.0" velocity="0.0"/>
  </joint>
  <joint name="joint_wheelR" type="revolute">
    <parent link="link_base"/>
    <child link="link_wheelR"/>
    <origin xyz="-0.40372  0       0.05" rpy="0 0 0"/>
    <axis xyz="-1  0  0"/>
    <limit lower="0.0" upper="6.283185307179586" effort="0.0" velocity="0.0"/>
  </joint>
  <joint name="joint_head" type="revolute">
    <parent link="link_base"/>
    <child link="link_head"/>
    <origin xyz="-1.2200e-03 -2.0000e-05  7.6541e-01" rpy="0 0 0"/>
    <axis xyz="0  0 -1"/>
    <limit lower="0.0" upper="6.283185307179586" effort="0.0" velocity="0.0"/>
  </joint>
  <link name="link_base">
    <inertial>
      <mass value="86.1777122467262"/>
      <origin xyz="0 0 0" rpy="0 0 0"/>
      <inertia ixx="6.443231636530824" ixy="0.0006993266805764146" ixz="0.002440526189443658" iyy="6.388071337224328" iyz="-0.0721928133558915" izz="1.802654637421469"/>
    </inertial>
    <collision name="link_base_collision">
      <origin xyz="-0.00079  0.00574  0.15327" rpy="0 0 0"/>
      <geometry>
        <mesh filename="package://PATHTOMESHES/meshes/CAD/link_base.stl" scale="0.001 0.001 0.001"/>
      </geometry>
    </collision>
    <visual name="link_base_visual">
      <origin xyz="-0.00079  0.00574  0.15327" rpy="0 0 0"/>
      <geometry>
        <mesh filename="package://PATHTOMESHES/meshes/CAD/link_base.stl" scale="0.001 0.001 0.001"/>
      </geometry>
    </visual>
  </link>
  <link name="link_head">
    <inertial>
      <mass value="12.991942687000781"/>
      <origin xyz="0 0 0" rpy="0 0 0"/>
      <inertia ixx="2.388752916509112" ixy="-2.016858265155722e-14" ixz="0.006571408800908258" iyy="2.445335065506726" iyz="9.873591670603138e-05" izz="0.06850544130681294"/>
    </inertial>
    <collision name="link_head_collision">
      <origin xyz="0       0      -0.33848" rpy="0 0 0"/>
      <geometry>
        <mesh filename="package://PATHTOMESHES/meshes/CAD/link_head.stl" scale="0.001 0.001 0.001"/>
      </geometry>
    </collision>
    <visual name="link_head_visual">
      <origin xyz="0       0      -0.33848" rpy="0 0 0"/>
      <geometry>
        <mesh filename="package://PATHTOMESHES/meshes/CAD/link_head.stl" scale="0.001 0.001 0.001"/>
      </geometry>
    </visual>
  </link>
  <link name="link_wheelR">
    <inertial>
      <mass value="28.6243419800856"/>
      <origin xyz="0 0 0" rpy="0 0 0"/>
      <inertia ixx="0.29162603877351306" ixy="-9.213086759204469e-11" ixz="0.1550933617807887" iyy="1.5078493950683804" iyz="1.0614348215103263e-11" izz="1.4899592180369656"/>
    </inertial>
    <collision name="link_wheelR_collision">
      <origin xyz="0.187  0    -0.025" rpy="0 0 0"/>
      <geometry>
        <mesh filename="package://PATHTOMESHES/meshes/CAD/link_wheelR.stl" scale="0.001 0.001 0.001"/>
      </geometry>
    </collision>
    <visual name="link_wheelR_visual">
      <origin xyz="0.187  0    -0.025" rpy="0 0 0"/>
      <geometry>
        <mesh filename="package://PATHTOMESHES/meshes/CAD/link_wheelR.stl" scale="0.001 0.001 0.001"/>
      </geometry>
    </visual>
  </link>
  <link name="link_wheelL">
    <inertial>
      <mass value="28.624341980085244"/>
      <origin xyz="0 0 0" rpy="0 0 0"/>
      <inertia ixx="0.2916260472200472" ixy="-5.8019409704087166e-11" ixz="-0.15509336178078806" iyy="1.5078494077381717" iyz="-6.684268011927254e-12" izz="1.489959213813678"/>
    </inertial>
    <collision name="link_wheelL_collision">
      <origin xyz="-0.187  0    -0.025" rpy="0 0 0"/>
      <geometry>
        <mesh filename="package://PATHTOMESHES/meshes/CAD/link_wheelL.stl" scale="0.001 0.001 0.001"/>
      </geometry>
    </collision>
    <visual name="link_wheelL_visual">
      <origin xyz="-0.187  0    -0.025" rpy="0 0 0"/>
      <geometry>
        <mesh filename="package://PATHTOMESHES/meshes/CAD/link_wheelL.stl" scale="0.001 0.001 0.001"/>
      </geometry>
    </visual>
  </link>
</robot>
